<robot name = "robot">
    <link name="Head">
        <inertial>
            <origin xyz="0 0 4.5040000000000004" rpy="0 0 0"/>
            <mass value="1" />
            <inertia ixx="100" ixy="0" ixz="0" iyy="100" iyz="0" izz="100" />
        </inertial>
        <visual>
            <origin xyz="0 0 4.5040000000000004" rpy="0 0 0"/>
            <geometry>
                <box size="0.5 0.5 0.325" />
            </geometry>
            <material name="Cyan">
                <color rgba="0 1.0 1.0 1.0"/>
            </material>
        </visual>
        <collision>
            <origin xyz="0 0 4.5040000000000004" rpy="0 0 0"/>
            <geometry>
                <box size="0.5 0.5 0.325" />
            </geometry>
        </collision>
    </link>
    <joint name="Head_Neck" type="revolute">
       <parent link="Head"/>
       <child  link="Neck"/>
       <origin rpy="0 0 0" xyz="0 0 4.418200000000001" />
     <axis xyz="0 0 1"/>
       <limit effort="0.0" lower="-3.14159" upper="3.14159" velocity="0.0"/>
    </joint>
    <link name="Neck">
        <inertial>
            <origin xyz="0 0 -0.25" rpy="0 0 0"/>
            <mass value="1" />
            <inertia ixx="100" ixy="0" ixz="0" iyy="100" iyz="0" izz="100" />
        </inertial>
        <visual>
            <origin xyz="0 0 -0.25" rpy="0 0 0"/>
            <geometry>
                <box size="0.325 0.325 0.264" />
            </geometry>
            <material name="Cyan">
                <color rgba="0 1.0 1.0 1.0"/>
            </material>
        </visual>
        <collision>
            <origin xyz="0 0 -0.25" rpy="0 0 0"/>
            <geometry>
                <box size="0.325 0.325 0.264" />
            </geometry>
        </collision>
    </link>
    <joint name="Neck_Torso" type="revolute">
       <parent link="Neck"/>
       <child  link="Torso"/>
       <origin rpy="0 0 0" xyz="0 0 -0.264" />
     <axis xyz="1 0 0"/>
       <limit effort="0.0" lower="-3.14159" upper="3.14159" velocity="0.0"/>
    </joint>
    <link name="Torso">
        <inertial>
            <origin xyz="0 0 -0.75" rpy="0 0 0"/>
            <mass value="1" />
            <inertia ixx="100" ixy="0" ixz="0" iyy="100" iyz="0" izz="100" />
        </inertial>
        <visual>
            <origin xyz="0 0 -0.75" rpy="0 0 0"/>
            <geometry>
                <box size="0.6 1.0 1.5" />
            </geometry>
            <material name="Cyan">
                <color rgba="0 1.0 1.0 1.0"/>
            </material>
        </visual>
        <collision>
            <origin xyz="0 0 -0.75" rpy="0 0 0"/>
            <geometry>
                <box size="0.6 1.0 1.5" />
            </geometry>
        </collision>
    </link>
    <joint name="Torso_Hip" type="revolute">
       <parent link="Torso"/>
       <child  link="Hip"/>
       <origin rpy="0 0 0" xyz="0 0 -1.5" />
     <axis xyz="0 1 0"/>
       <limit effort="0.0" lower="-3.14159" upper="3.14159" velocity="0.0"/>
    </joint>
    <link name="Hip">
        <inertial>
            <origin xyz="0 0 -0.125" rpy="0 0 0"/>
            <mass value="1" />
            <inertia ixx="100" ixy="0" ixz="0" iyy="100" iyz="0" izz="100" />
        </inertial>
        <visual>
            <origin xyz="0 0 -0.125" rpy="0 0 0"/>
            <geometry>
                <box size="0.6 1.0 0.25" />
            </geometry>
            <material name="Cyan">
                <color rgba="0 1.0 1.0 1.0"/>
            </material>
        </visual>
        <collision>
            <origin xyz="0 0 -0.125" rpy="0 0 0"/>
            <geometry>
                <box size="0.6 1.0 0.25" />
            </geometry>
        </collision>
    </link>
    <joint name="Hip_UpperLleg" type="revolute">
       <parent link="Hip"/>
       <child  link="UpperLleg"/>
       <origin rpy="0 0 0" xyz="0 -0.625 -0.25" />
     <axis xyz="0 1 0"/>
       <limit effort="0.0" lower="-3.14159" upper="3.14159" velocity="0.0"/>
    </joint>
    <link name="UpperLleg">
        <inertial>
            <origin xyz="0 0 -0.5" rpy="0 0 0"/>
            <mass value="1" />
            <inertia ixx="100" ixy="0" ixz="0" iyy="100" iyz="0" izz="100" />
        </inertial>
        <visual>
            <origin xyz="0 0 -0.5" rpy="0 0 0"/>
            <geometry>
                <box size="0.52 0.325 1.0" />
            </geometry>
            <material name="Cyan">
                <color rgba="0 1.0 1.0 1.0"/>
            </material>
        </visual>
        <collision>
            <origin xyz="0 0 -0.5" rpy="0 0 0"/>
            <geometry>
                <box size="0.52 0.325 1.0" />
            </geometry>
        </collision>
    </link>
    <joint name="Hip_UpperRleg" type="revolute">
       <parent link="Hip"/>
       <child  link="UpperRleg"/>
       <origin rpy="0 0 0" xyz="0 0.625 -0.25" />
     <axis xyz="0 1 0"/>
       <limit effort="0.0" lower="-3.14159" upper="3.14159" velocity="0.0"/>
    </joint>
    <link name="UpperRleg">
        <inertial>
            <origin xyz="0 0 -0.5" rpy="0 0 0"/>
            <mass value="1" />
            <inertia ixx="100" ixy="0" ixz="0" iyy="100" iyz="0" izz="100" />
        </inertial>
        <visual>
            <origin xyz="0 0 -0.5" rpy="0 0 0"/>
            <geometry>
                <box size="0.52 0.325 1.0" />
            </geometry>
            <material name="Cyan">
                <color rgba="0 1.0 1.0 1.0"/>
            </material>
        </visual>
        <collision>
            <origin xyz="0 0 -0.5" rpy="0 0 0"/>
            <geometry>
                <box size="0.52 0.325 1.0" />
            </geometry>
        </collision>
    </link>
    <joint name="UpperLleg_LowerLleg" type="revolute">
       <parent link="UpperLleg"/>
       <child  link="LowerLleg"/>
       <origin rpy="0 0 0" xyz="0 0 -1.0" />
     <axis xyz="0 1 0"/>
       <limit effort="0.0" lower="-3.14159" upper="3.14159" velocity="0.0"/>
    </joint>
    <link name="LowerLleg">
        <inertial>
            <origin xyz="0 0 -0.625" rpy="0 0 0"/>
            <mass value="1" />
            <inertia ixx="100" ixy="0" ixz="0" iyy="100" iyz="0" izz="100" />
        </inertial>
        <visual>
            <origin xyz="0 0 -0.625" rpy="0 0 0"/>
            <geometry>
                <box size="0.4 0.25 1.25" />
            </geometry>
            <material name="Cyan">
                <color rgba="0 1.0 1.0 1.0"/>
            </material>
        </visual>
        <collision>
            <origin xyz="0 0 -0.625" rpy="0 0 0"/>
            <geometry>
                <box size="0.4 0.25 1.25" />
            </geometry>
        </collision>
    </link>
    <joint name="UpperRleg_LowerRleg" type="revolute">
       <parent link="UpperRleg"/>
       <child  link="LowerRleg"/>
       <origin rpy="0 0 0" xyz="0 0 -1.0" />
     <axis xyz="0 1 0"/>
       <limit effort="0.0" lower="-3.14159" upper="3.14159" velocity="0.0"/>
    </joint>
    <link name="LowerRleg">
        <inertial>
            <origin xyz="0 0 -0.625" rpy="0 0 0"/>
            <mass value="1" />
            <inertia ixx="100" ixy="0" ixz="0" iyy="100" iyz="0" izz="100" />
        </inertial>
        <visual>
            <origin xyz="0 0 -0.625" rpy="0 0 0"/>
            <geometry>
                <box size="0.4 0.25 1.25" />
            </geometry>
            <material name="Cyan">
                <color rgba="0 1.0 1.0 1.0"/>
            </material>
        </visual>
        <collision>
            <origin xyz="0 0 -0.625" rpy="0 0 0"/>
            <geometry>
                <box size="0.4 0.25 1.25" />
            </geometry>
        </collision>
    </link>
    <joint name="LowerLleg_LFoot" type="revolute">
       <parent link="LowerLleg"/>
       <child  link="LFoot"/>
       <origin rpy="0 0 0" xyz="0.15 0 -1.25" />
     <axis xyz="0 1 0"/>
       <limit effort="0.0" lower="-3.14159" upper="3.14159" velocity="0.0"/>
    </joint>
    <link name="LFoot">
        <inertial>
            <origin xyz="0.078125 0 -0.0825" rpy="0 0 0"/>
            <mass value="1" />
            <inertia ixx="100" ixy="0" ixz="0" iyy="100" iyz="0" izz="100" />
        </inertial>
        <visual>
            <origin xyz="0.078125 0 -0.0825" rpy="0 0 0"/>
            <geometry>
                <box size="0.625 0.4 0.165" />
            </geometry>
            <material name="Cyan">
                <color rgba="0 1.0 1.0 1.0"/>
            </material>
        </visual>
        <collision>
            <origin xyz="0.078125 0 -0.0825" rpy="0 0 0"/>
            <geometry>
                <box size="0.625 0.4 0.165" />
            </geometry>
        </collision>
    </link>
    <joint name="LowerRleg_RFoot" type="revolute">
       <parent link="LowerRleg"/>
       <child  link="RFoot"/>
       <origin rpy="0 0 0" xyz="0.15 0 -1.25" />
     <axis xyz="0 1 0"/>
       <limit effort="0.0" lower="-3.14159" upper="3.14159" velocity="0.0"/>
    </joint>
    <link name="RFoot">
        <inertial>
            <origin xyz="0.078125 0 -0.0825" rpy="0 0 0"/>
            <mass value="1" />
            <inertia ixx="100" ixy="0" ixz="0" iyy="100" iyz="0" izz="100" />
        </inertial>
        <visual>
            <origin xyz="0.078125 0 -0.0825" rpy="0 0 0"/>
            <geometry>
                <box size="0.625 0.4 0.165" />
            </geometry>
            <material name="Cyan">
                <color rgba="0 1.0 1.0 1.0"/>
            </material>
        </visual>
        <collision>
            <origin xyz="0.078125 0 -0.0825" rpy="0 0 0"/>
            <geometry>
                <box size="0.625 0.4 0.165" />
            </geometry>
        </collision>
    </link>
    <joint name="Torso_Lshoulder" type="revolute">
       <parent link="Torso"/>
       <child  link="Lshoulder"/>
       <origin rpy="0 0 0" xyz="0 -0.5 -0.25" />
     <axis xyz="1 1 0"/>
       <limit effort="0.0" lower="-3.14159" upper="3.14159" velocity="0.0"/>
    </joint>
    <link name="Lshoulder">
        <inertial>
            <origin xyz="0 -0.05 0" rpy="0 0 0"/>
            <mass value="1" />
            <inertia ixx="100" ixy="0" ixz="0" iyy="100" iyz="0" izz="100" />
        </inertial>
        <visual>
            <origin xyz="0 -0.05 0" rpy="0 0 0"/>
            <geometry>
                <box size="0.5 0.1 0.2" />
            </geometry>
            <material name="Cyan">
                <color rgba="0 1.0 1.0 1.0"/>
            </material>
        </visual>
        <collision>
            <origin xyz="0 -0.05 0" rpy="0 0 0"/>
            <geometry>
                <box size="0.5 0.1 0.2" />
            </geometry>
        </collision>
    </link>
    <joint name="Torso_Rshoulder" type="revolute">
       <parent link="Torso"/>
       <child  link="Rshoulder"/>
       <origin rpy="0 0 0" xyz="0 0.5 -0.25" />
     <axis xyz="1 1 0"/>
       <limit effort="0.0" lower="-3.14159" upper="3.14159" velocity="0.0"/>
    </joint>
    <link name="Rshoulder">
        <inertial>
            <origin xyz="0 0.05 0" rpy="0 0 0"/>
            <mass value="1" />
            <inertia ixx="100" ixy="0" ixz="0" iyy="100" iyz="0" izz="100" />
        </inertial>
        <visual>
            <origin xyz="0 0.05 0" rpy="0 0 0"/>
            <geometry>
                <box size="0.5 0.1 0.2" />
            </geometry>
            <material name="Cyan">
                <color rgba="0 1.0 1.0 1.0"/>
            </material>
        </visual>
        <collision>
            <origin xyz="0 0.05 0" rpy="0 0 0"/>
            <geometry>
                <box size="0.5 0.1 0.2" />
            </geometry>
        </collision>
    </link>
    <joint name="Lshoulder_LUpperArm" type="revolute">
       <parent link="Lshoulder"/>
       <child  link="LUpperArm"/>
       <origin rpy="0 0 0" xyz="0 -0.1 0.07" />
     <axis xyz="0 1 0"/>
       <limit effort="0.0" lower="-3.14159" upper="3.14159" velocity="0.0"/>
    </joint>
    <link name="LUpperArm">
        <inertial>
            <origin xyz="0 -0.125 -0.35000000000000003" rpy="0 0 0"/>
            <mass value="1" />
            <inertia ixx="100" ixy="0" ixz="0" iyy="100" iyz="0" izz="100" />
        </inertial>
        <visual>
            <origin xyz="0 -0.125 -0.35000000000000003" rpy="0 0 0"/>
            <geometry>
                <box size="0.2 0.25 0.7000000000000001" />
            </geometry>
            <material name="Cyan">
                <color rgba="0 1.0 1.0 1.0"/>
            </material>
        </visual>
        <collision>
            <origin xyz="0 -0.125 -0.35000000000000003" rpy="0 0 0"/>
            <geometry>
                <box size="0.2 0.25 0.7000000000000001" />
            </geometry>
        </collision>
    </link>
    <joint name="LUpperArm_LLowerArm" type="revolute">
       <parent link="LUpperArm"/>
       <child  link="LLowerArm"/>
       <origin rpy="0 0 0" xyz="0 -0.125 -0.7000000000000001" />
     <axis xyz="0 1 0"/>
       <limit effort="0.0" lower="-3.14159" upper="3.14159" velocity="0.0"/>
    </joint>
    <link name="LLowerArm">
        <inertial>
            <origin xyz="0 0 -0.35000000000000003" rpy="0 0 0"/>
            <mass value="1" />
            <inertia ixx="100" ixy="0" ixz="0" iyy="100" iyz="0" izz="100" />
        </inertial>
        <visual>
            <origin xyz="0 0 -0.35000000000000003" rpy="0 0 0"/>
            <geometry>
                <box size="0.25 0.25 0.7000000000000001" />
            </geometry>
            <material name="Cyan">
                <color rgba="0 1.0 1.0 1.0"/>
            </material>
        </visual>
        <collision>
            <origin xyz="0 0 -0.35000000000000003" rpy="0 0 0"/>
            <geometry>
                <box size="0.25 0.25 0.7000000000000001" />
            </geometry>
        </collision>
    </link>
    <joint name="Rshoulder_RUpperArm" type="revolute">
       <parent link="Rshoulder"/>
       <child  link="RUpperArm"/>
       <origin rpy="0 0 0" xyz="0 0.1 0.07" />
     <axis xyz="0 1 0"/>
       <limit effort="0.0" lower="-3.14159" upper="3.14159" velocity="0.0"/>
    </joint>
    <link name="RUpperArm">
        <inertial>
            <origin xyz="0 0.125 -0.35000000000000003" rpy="0 0 0"/>
            <mass value="1" />
            <inertia ixx="100" ixy="0" ixz="0" iyy="100" iyz="0" izz="100" />
        </inertial>
        <visual>
            <origin xyz="0 0.125 -0.35000000000000003" rpy="0 0 0"/>
            <geometry>
                <box size="0.2 0.25 0.7000000000000001" />
            </geometry>
            <material name="Cyan">
                <color rgba="0 1.0 1.0 1.0"/>
            </material>
        </visual>
        <collision>
            <origin xyz="0 0.125 -0.35000000000000003" rpy="0 0 0"/>
            <geometry>
                <box size="0.2 0.25 0.7000000000000001" />
            </geometry>
        </collision>
    </link>
    <joint name="RUpperArm_RLowerArm" type="revolute">
       <parent link="RUpperArm"/>
       <child  link="RLowerArm"/>
       <origin rpy="0 0 0" xyz="0 0.125 -0.7000000000000001" />
     <axis xyz="0 1 0"/>
       <limit effort="0.0" lower="-3.14159" upper="3.14159" velocity="0.0"/>
    </joint>
    <link name="RLowerArm">
        <inertial>
            <origin xyz="0 0 -0.35000000000000003" rpy="0 0 0"/>
            <mass value="1" />
            <inertia ixx="100" ixy="0" ixz="0" iyy="100" iyz="0" izz="100" />
        </inertial>
        <visual>
            <origin xyz="0 0 -0.35000000000000003" rpy="0 0 0"/>
            <geometry>
                <box size="0.25 0.25 0.7000000000000001" />
            </geometry>
            <material name="Cyan">
                <color rgba="0 1.0 1.0 1.0"/>
            </material>
        </visual>
        <collision>
            <origin xyz="0 0 -0.35000000000000003" rpy="0 0 0"/>
            <geometry>
                <box size="0.25 0.25 0.7000000000000001" />
            </geometry>
        </collision>
    </link>
</robot>