<robot name = "robot">
    <link name="Head">
        <inertial>
            <origin xyz="0 0 8.81" rpy="0 0 0"/>
            <mass value="1" />
            <inertia ixx="100" ixy="0" ixz="0" iyy="100" iyz="0" izz="100" />
        </inertial>
        <visual>
            <origin xyz="0 0 8.81" rpy="0 0 0"/>
            <geometry>
                <box size="1 1 0.65" />
            </geometry>
            <material name="Cyan">
                <color rgba="0 1.0 1.0 1.0"/>
            </material>
        </visual>
        <collision>
            <origin xyz="0 0 8.81" rpy="0 0 0"/>
            <geometry>
                <box size="1 1 0.65" />
            </geometry>
        </collision>
    </link>
    <joint name="Head_Neck" type="revolute">
       <parent link="Head"/>
       <child  link="Neck"/>
       <origin rpy="0 0 0" xyz="0 0 8.595500000000001" />
     <axis xyz="0 0 1"/>
       <limit effort="0.0" lower="-3.14159" upper="3.14159" velocity="0.0"/>
    </joint>
    <link name="Neck">
        <inertial>
            <origin xyz="0 0 -0.25" rpy="0 0 0"/>
            <mass value="1" />
            <inertia ixx="100" ixy="0" ixz="0" iyy="100" iyz="0" izz="100" />
        </inertial>
        <visual>
            <origin xyz="0 0 -0.25" rpy="0 0 0"/>
            <geometry>
                <box size="0.65 0.65 0.33" />
            </geometry>
            <material name="Cyan">
                <color rgba="0 1.0 1.0 1.0"/>
            </material>
        </visual>
        <collision>
            <origin xyz="0 0 -0.25" rpy="0 0 0"/>
            <geometry>
                <box size="0.65 0.65 0.33" />
            </geometry>
        </collision>
    </link>
    <joint name="Neck_Torso" type="revolute">
       <parent link="Neck"/>
       <child  link="Torso"/>
       <origin rpy="0 0 0" xyz="0 0 -0.33" />
     <axis xyz="1 0 0"/>
       <limit effort="0.0" lower="-3.14159" upper="3.14159" velocity="0.0"/>
    </joint>
    <link name="Torso">
        <inertial>
            <origin xyz="0 0 -1.5" rpy="0 0 0"/>
            <mass value="1" />
            <inertia ixx="100" ixy="0" ixz="0" iyy="100" iyz="0" izz="100" />
        </inertial>
        <visual>
            <origin xyz="0 0 -1.5" rpy="0 0 0"/>
            <geometry>
                <box size="1.2 2 3" />
            </geometry>
            <material name="Cyan">
                <color rgba="0 1.0 1.0 1.0"/>
            </material>
        </visual>
        <collision>
            <origin xyz="0 0 -1.5" rpy="0 0 0"/>
            <geometry>
                <box size="1.2 2 3" />
            </geometry>
        </collision>
    </link>
    <joint name="Torso_Hip" type="revolute">
       <parent link="Torso"/>
       <child  link="Hip"/>
       <origin rpy="0 0 0" xyz="0 0 -3" />
     <axis xyz="0 1 0"/>
       <limit effort="0.0" lower="-3.14159" upper="3.14159" velocity="0.0"/>
    </joint>
    <link name="Hip">
        <inertial>
            <origin xyz="0 0 -0.125" rpy="0 0 0"/>
            <mass value="1" />
            <inertia ixx="100" ixy="0" ixz="0" iyy="100" iyz="0" izz="100" />
        </inertial>
        <visual>
            <origin xyz="0 0 -0.125" rpy="0 0 0"/>
            <geometry>
                <box size="0.75 2 0.25" />
            </geometry>
            <material name="Cyan">
                <color rgba="0 1.0 1.0 1.0"/>
            </material>
        </visual>
        <collision>
            <origin xyz="0 0 -0.125" rpy="0 0 0"/>
            <geometry>
                <box size="0.75 2 0.25" />
            </geometry>
        </collision>
    </link>
    <joint name="Hip_UpperLleg" type="revolute">
       <parent link="Hip"/>
       <child  link="UpperLleg"/>
       <origin rpy="0 0 0" xyz="0 -0.625 -0.25" />
     <axis xyz="0 1 0"/>
       <limit effort="0.0" lower="-3.14159" upper="3.14159" velocity="0.0"/>
    </joint>
    <link name="UpperLleg">
        <inertial>
            <origin xyz="0 0 -1.0" rpy="0 0 0"/>
            <mass value="1" />
            <inertia ixx="100" ixy="0" ixz="0" iyy="100" iyz="0" izz="100" />
        </inertial>
        <visual>
            <origin xyz="0 0 -1.0" rpy="0 0 0"/>
            <geometry>
                <box size="0.65 0.65 2" />
            </geometry>
            <material name="Cyan">
                <color rgba="0 1.0 1.0 1.0"/>
            </material>
        </visual>
        <collision>
            <origin xyz="0 0 -1.0" rpy="0 0 0"/>
            <geometry>
                <box size="0.65 0.65 2" />
            </geometry>
        </collision>
    </link>
    <joint name="Hip_UpperRleg" type="revolute">
       <parent link="Hip"/>
       <child  link="UpperRleg"/>
       <origin rpy="0 0 0" xyz="0 0.625 -0.25" />
     <axis xyz="0 1 0"/>
       <limit effort="0.0" lower="-3.14159" upper="3.14159" velocity="0.0"/>
    </joint>
    <link name="UpperRleg">
        <inertial>
            <origin xyz="0 0 -1.0" rpy="0 0 0"/>
            <mass value="1" />
            <inertia ixx="100" ixy="0" ixz="0" iyy="100" iyz="0" izz="100" />
        </inertial>
        <visual>
            <origin xyz="0 0 -1.0" rpy="0 0 0"/>
            <geometry>
                <box size="0.65 0.65 2" />
            </geometry>
            <material name="Cyan">
                <color rgba="0 1.0 1.0 1.0"/>
            </material>
        </visual>
        <collision>
            <origin xyz="0 0 -1.0" rpy="0 0 0"/>
            <geometry>
                <box size="0.65 0.65 2" />
            </geometry>
        </collision>
    </link>
    <joint name="UpperLleg_LowerLleg" type="revolute">
       <parent link="UpperLleg"/>
       <child  link="LowerLleg"/>
       <origin rpy="0 0 0" xyz="0 0 -2" />
     <axis xyz="0 1 0"/>
       <limit effort="0.0" lower="-3.14159" upper="3.14159" velocity="0.0"/>
    </joint>
    <link name="LowerLleg">
        <inertial>
            <origin xyz="0 0 -1.25" rpy="0 0 0"/>
            <mass value="1" />
            <inertia ixx="100" ixy="0" ixz="0" iyy="100" iyz="0" izz="100" />
        </inertial>
        <visual>
            <origin xyz="0 0 -1.25" rpy="0 0 0"/>
            <geometry>
                <box size="0.5 0.5 2.5" />
            </geometry>
            <material name="Cyan">
                <color rgba="0 1.0 1.0 1.0"/>
            </material>
        </visual>
        <collision>
            <origin xyz="0 0 -1.25" rpy="0 0 0"/>
            <geometry>
                <box size="0.5 0.5 2.5" />
            </geometry>
        </collision>
    </link>
    <joint name="UpperRleg_LowerRleg" type="revolute">
       <parent link="UpperRleg"/>
       <child  link="LowerRleg"/>
       <origin rpy="0 0 0" xyz="0 0 -2" />
     <axis xyz="0 1 0"/>
       <limit effort="0.0" lower="-3.14159" upper="3.14159" velocity="0.0"/>
    </joint>
    <link name="LowerRleg">
        <inertial>
            <origin xyz="0 0 -1.25" rpy="0 0 0"/>
            <mass value="1" />
            <inertia ixx="100" ixy="0" ixz="0" iyy="100" iyz="0" izz="100" />
        </inertial>
        <visual>
            <origin xyz="0 0 -1.25" rpy="0 0 0"/>
            <geometry>
                <box size="0.5 0.5 2.5" />
            </geometry>
            <material name="Cyan">
                <color rgba="0 1.0 1.0 1.0"/>
            </material>
        </visual>
        <collision>
            <origin xyz="0 0 -1.25" rpy="0 0 0"/>
            <geometry>
                <box size="0.5 0.5 2.5" />
            </geometry>
        </collision>
    </link>
    <joint name="LowerLleg_LFoot" type="revolute">
       <parent link="LowerLleg"/>
       <child  link="LFoot"/>
       <origin rpy="0 0 0" xyz="0.15 0 -2.5" />
     <axis xyz="0 1 0"/>
       <limit effort="0.0" lower="-3.14159" upper="3.14159" velocity="0.0"/>
    </joint>
    <link name="LFoot">
        <inertial>
            <origin xyz="0.15625 0 -0.165" rpy="0 0 0"/>
            <mass value="1" />
            <inertia ixx="100" ixy="0" ixz="0" iyy="100" iyz="0" izz="100" />
        </inertial>
        <visual>
            <origin xyz="0.15625 0 -0.165" rpy="0 0 0"/>
            <geometry>
                <box size="1.25 0.4 0.33" />
            </geometry>
            <material name="Cyan">
                <color rgba="0 1.0 1.0 1.0"/>
            </material>
        </visual>
        <collision>
            <origin xyz="0.15625 0 -0.165" rpy="0 0 0"/>
            <geometry>
                <box size="1.25 0.4 0.33" />
            </geometry>
        </collision>
    </link>
    <joint name="LowerRleg_RFoot" type="revolute">
       <parent link="LowerRleg"/>
       <child  link="RFoot"/>
       <origin rpy="0 0 0" xyz="0.15 0 -2.5" />
     <axis xyz="0 1 0"/>
       <limit effort="0.0" lower="-3.14159" upper="3.14159" velocity="0.0"/>
    </joint>
    <link name="RFoot">
        <inertial>
            <origin xyz="0.15625 0 -0.165" rpy="0 0 0"/>
            <mass value="1" />
            <inertia ixx="100" ixy="0" ixz="0" iyy="100" iyz="0" izz="100" />
        </inertial>
        <visual>
            <origin xyz="0.15625 0 -0.165" rpy="0 0 0"/>
            <geometry>
                <box size="1.25 0.4 0.33" />
            </geometry>
            <material name="Cyan">
                <color rgba="0 1.0 1.0 1.0"/>
            </material>
        </visual>
        <collision>
            <origin xyz="0.15625 0 -0.165" rpy="0 0 0"/>
            <geometry>
                <box size="1.25 0.4 0.33" />
            </geometry>
        </collision>
    </link>
</robot>